Workbook

Sheet Customer Table
A1: Customer_ID | B1: Name | C1: Age | D1: Gender | E1: City | F1: State | G1: Country | H1: Loyalty_Level
A2: CUST1000 | B2: Sheena Bonilla | C2: 55 | D2: Male | E2: Donaldton | F2: North Carolina | G2: USA | H2: Unknown
A3: CUST1001 | B3: Eugene Nelson | C3: 26 | D3: Female | E3: Phillipsmouth | F3: North Dakota | G3: USA | H3: Platinum
A4: CUST1002 | B4: Dr. Benjamin Price | C4: 29 | D4: Female | E4: Kylebury | F4: Alabama | G4: USA | H4: Platinum
A5: CUST1003 | B5: Jeremy Harris | C5: 59 | D5: Female | E5: Thomastown | F5: Ohio | G5: USA | H5: Bronze | J5: Row Labels | K5: Count of Customer_ID
A6: CUST1004 | B6: Caroline Collins | C6: 64 | D6: Female | E6: Nicholasshire | F6: California | G6: USA | H6: Silver | J6: Female | K6: 262
A7: CUST1005 | B7: Christine Vaughn | C7: 24 | D7: Male | E7: East Amandamouth | F7: Oregon | G7: USA | H7: Bronze | J7: Male | K7: 238
A8: CUST1006 | B8: Amber Jackson | C8: 29 | D8: Female | E8: Deborahborough | F8: South Dakota | G8: USA | H8: Platinum | J8: (blank)
A9: CUST1007 | B9: Daniel Boyd | C9: 29 | D9: Female | E9: West Pamelafurt | F9: West Virginia | G9: USA | H9: Bronze | J9: Grand Total | K9: 500
A10: CUST1008 | B10: Melissa Howard | C10: 53 | D10: Female | E10: Maynardton | F10: New Hampshire | G10: USA | H10: Gold
A11: CUST1009 | B11: Ms. Maria Leach | C11: 64 | D11: Male | E11: Melissashire | F11: Pennsylvania | G11: USA | H11: Platinum
A12: CUST1010 | B12: Dominic Page | C12: 53 | D12: Male | E12: Port Michaelburgh | F12: Pennsylvania | G12: USA | H12: Bronze
A13: CUST1011 | B13: Brian Lopez | C13: 28 | D13: Female | E13: East Krista | F13: New York | G13: USA | H13: Gold
A14: CUST1012 | B14: Kenneth Lambert | C14: 55 | D14: Female | E14: North Kathryn | F14: Kansas | G14: USA | H14: Platinum
A15: CUST1013 | B15: Nathan Hernandez | C15: 32 | D15: Female | E15: New Becky | F15: Montana | G15: USA | H15: Silver
A16: CUST1014 | B16: Ashley Cohen | C16: 53 | D16: Female | E16: Lake Kristamouth | F16: Nebraska | G16: USA | H16: Silver
A17: CUST1015 | B17: Laura Alvarez | C17: 49 | D17: Female | E17: Lawsonhaven | F17: Washington | G17: USA | H17: Platinum
A18: CUST1016 | B18: John Scott | C18: 24 | D18: Female | E18: South Christopher | F18: Pennsylvania | G18: USA | H18: Bronze
A19: CUST1017 | B19: Adam Cruz | C19: 60 | D19: Female | E19: Brandonville | F19: Georgia | G19: USA | H19: Platinum
A20: CUST1018 | B20: Rhonda Moss | C20: 43 | D20: Male | E20: South William | F20: Kansas | G20: USA | H20: Unknown
A21: CUST1019 | B21: Michael Torres | C21: 46 | D21: Female | E21: Gonzalezfort | F21: New Jersey | G21: USA | H21: Platinum
... A501: CUST1499 | B501: Philip Pennington | C501: 27 | D501: Female | E501: East Valerieview | F501: Oregon | G501: USA | H501: Platinum

Sheet Product_Dim
A1: Product_ID | B1: Product_Name | C1: Category | D1: Sub_Category | E1: Brand | F1: Cost | G1: Stock
A2: PROD0 | B2: Brother Laser Printer | C2: Electronics | D2: Computer | E2: Hunt Inc | F2: 112.42 | G2: 416
A3: PROD1 | B3: Men's Graphic T-Shirt | C3: Clothing | D3: Tops | E3: Terry-Moore | F3: 342.56 | G3: 181
A4: PROD2 | B4: Women's Casual Hoodie | C4: Clothing | D4: Outerwear | E4: Sims Inc | G4: 352 | I4: Row Labels | J4: Count of Product_ID | M4: Row Labels | N4: Count of Product_ID
A5: PROD3 | B5: Men's Running Jacket | C5: Clothing | D5: Outerwear | E5: Pineda Ltd | F5: 364.67 | G5: 452 | I5: Beauty | J5: 15 | M5: Beauty | N5: 15
A6: PROD4 | B6: Women's Yoga Pants | C6: Clothing | D6: Bottoms | E6: Gonzales-Davis | F6: 306.46 | G6: 487 | I6: Clothing | J6: 18 | M6: Clothing | N6: 18
A7: PROD5 | B7: Men's Leather Belt | C7: Clothing | D7: Accessories | E7: Baldwin, Garza and Gonzalez | F7: 261 | G7: 59 | I7: Electronics | J7: 21 | M7: Electronics | N7: 21
A8: PROD6 | B8: Herbal Face Moisturizer | C8: Beauty | D8: Skincare | E8: Davidson PLC | F8: 312.8 | G8: 350 | I8: Home | J8: 21 | M8: Home | N8: 21
A9: PROD7 | B9: LED Table Lamp | C9: Home | D9: Lighting | E9: Harrell LLC | F9: 218.86 | G9: 170 | I9: Sports | J9: 25 | M9: Sports | N9: 25
A10: PROD8 | B10: Wireless Bluetooth Earbuds | C10: Electronics | D10: Audio | E10: Perez-Johnston | F10: 439.07 | G10: 142 | I10: (blank) | M10: Grand Total | N10: 100
A11: PROD9 | B11: Adjustable Dumbbell Set | C11: Sports | D11: Fitness | E11: Hill PLC | F11: 495.72 | G11: 323 | I11: Grand Total | J11: 100
A12: PROD10 | B12: Ceramic Kitchen Bowl Set | C12: Home | D12: Kitchen | E12: Hamilton Group | F12: 298.86 | G12: 308
A13: PROD11 | B13: HD Smart TV Stick | C13: Electronics | D13: Accessories | E13: Gibson, Hobbs and Weaver | F13: 449.4
A14: PROD12 | B14: Hair Strengthening Shampoo | C14: Beauty | D14: Haircare | E14: Rice LLC | F14: 115.82 | G14: 460
A15: PROD13 | B15: USB-C Fast Charger | C15: Electronics | D15: Accessories | E15: Dawson-Perkins | F15: 242.23 | G15: 453
A16: PROD14 | B16: Decorative Wall Mirror | C16: Home | D16: Decor | E16: Luna, Anderson and Bowman | F16: 48.01 | G16: 439
A17: PROD15 | B17: 4K Home Projector | C17: Electronics | D17: Appliances | E17: Thomas LLC | F17: 465.34 | G17: 301
A18: PROD16 | B18: Beard Grooming Kit | C18: Beauty | D18: Grooming | E18: Erickson-Green | F18: 337.42 | G18: 256
A19: PROD17 | B19: Soccer Training Cone Set | C19: Sports | D19: Accessories | E19: Ford, Murphy and Wilson | F19: 144.53 | G19: 367
A20: PROD18 | B20: Women's Denim Jeans | C20: Clothing | D20: Bottoms | E20: Guerra-Hendrix | G20: 343
A21: PROD19 | B21: Knee Support Brace | C21: Sports | D21: Equipment | E21: May-Reese | F21: 21.34 | G21: 65
A22: PROD20 | B22: Outdoor Sports Water Bottle | C22: Sports | D22: Accessories | E22: Soto-Ellis | F22: 131.51
A23: PROD21 | B23: Multi-Purpose Storage Box | C23: Home | D23: Storage | E23: Gardner-Montes | F23: 123.46 | G23: 76
A24: PROD22 | B24: Carbon Fiber Tennis Racket | C24: Sports | D24: Equipment | E24: Flores, Pineda and Rodriguez | F24: 484.62 | G24: 432
A25: PROD23 | B25: Men's Formal Shirt | C25: Clothing | D25: Tops | E25: Moon, Mora and Santos | G25: 360
A26: PROD24 | B26: Foldable Camping Chair | C26: Sports | D26: Outdoor | E26: Cook Ltd | F26: 166.06 | G26: 340
A27: PROD25 | B27: Women's Scarf Set | C27: Clothing | D27: Accessories | E27: Brown and Sons | F27: 174.02 | G27: 268
A28: PROD26 | B28: Wireless Bluetooth Speaker | C28: Electronics | D28: Audio | E28: Reed-Schmidt | F28: 322.41 | G28: 213
A29: PROD27 | B29: Decorative Floor Vase | C29: Home | D29: Decor | E29: Khan, Jones and Paul | G29: 378
A30: PROD28 | B30: Sports Stopwatch Timer | C30: Sports | D30: Accessories | E30: Burns-Hansen | F30: 38.76 | G30: 137
A31: PROD29 | B31: Fabric Sofa Throw Blanket | C31: Home | D31: Decor | E31: Hoffman Group | F31: 218.48 | G31: 276
A32: PROD30 | B32: Stainless Steel Cutlery Set | C32: Home | D32: Kitchen | E32: Stevens, Fernandez and Martin | F32: 19.52 | G32: 57
A33: PROD31 | B33: Basketball | C33: Sports | D33: Team Sports | E33: Nolan-Snow | F33: 204.39 | G33: 281
A34: PROD32 | B34: Vitamin C Face Serum | C34: Beauty | D34: Skincare | E34: Griffin Ltd | F34: 283.83 | G34: 244
A35: PROD33 | B35: Modern Wall Clock | C35: Home | D35: Decor | E35: Weiss-Watson | F35: 179.77 | G35: 305
A36: PROD34 | B36: Gaming Mechanical Keyboard | C36: Electronics | D36: Computer | E36: Lucero LLC | F36: 419.28 | G36: 86
A37: PROD35 | B37: Bedroom Table Lamp | C37: Home | D37: Lighting | E37: Jones LLC | F37: 382.22 | G37: 329
A38: PROD36 | B38: Women's Summer Dress | C38: Clothing | D38: Tops | E38: Smith-Mills | F38: 223.43 | G38: 154
A39: PROD37 | B39: Men's Casual Sneakers | C39: Clothing | D39: Footwear | E39: Hogan-Lee | F39: 353.47 | G39: 214
A40: PROD38 | B40: Sports Water Hydration Pack | C40: Sports | D40: Outdoor | E40: Sims-Smith | F40: 135.61 | G40: 394
...

Sheet Store_Dim
A1: Store_ID | B1: Store_Name | C1: Region | D1: City | E1: Store_Type
A2: STORE0 | B2: Rivera-Warner | C2: East | D2: Washingtonfurt | E2: Flagship
A3: STORE1 | B3: Martinez, Adkins and Johnson | C3: North | D3: Danielmouth | E3: Flagship
A4: STORE2 | B4: Black-Horn | C4: South | D4: North Nancyview | E4: Outlet
A5: STORE3 | B5: Johnson-Wright | C5: North | D5: Hoodberg | E5: Outlet
A6: STORE4 | B6: Alexander Group | C6: South | D6: Port Sharon | E6: Online
A7: STORE5 | B7: Gray Ltd | C7: North | D7: New Michaelchester | E7: Outlet
A8: STORE6 | B8: Benson-Elliott | C8: East | D8: Port Josephberg | E8: Online
A9: STORE7 | B9: Martinez-Mullins | C9: South | D9: Williamsfurt | E9: Online
A10: STORE8 | B10: Bean, Jones and Park | C10: West | D10: Thompsonborough | E10: Online
A11: STORE9 | B11: Moore, Padilla and Butler | C11: South | D11: East Johnstad | E11: Flagship
A12: STORE10 | B12: Hill, Wagner and Ballard | C12: East | D12: East Davidville | E12: Online
... A21: STORE19 | B21: Mann-Austin | C21: East | D21: Vasquezborough | E21: Online

Sheet Sales_Fact
A1: Sales_ID | B1: Order_Date | C1: Customer_ID | D1: Product_ID | E1: Store_ID | F1: Quantity | G1: Unit_Price | H1: Discount | I1: Payment_Type | J1: Total_Amount | K1: Total sales | L1: Avg sales | M1: Count transby pyt | N1: High or low value | O1: Extract month and year | P1: Product_Name | Q1: Category | R1: Customer Name
A2: SALE0 | B2: 45480 | C2: CUST1409 | D2: PROD97 | E2: STORE3 | F2: 1 | G2: 218.04 | H2: 0.09 | I2: Credit Card | J2: 198.4164 | K2: =SUM(J2:J2001) -> 2174394.7 | L2: =AVERAGE(J2:J2001) -> 1087.1973 | M2: =COUNTIF(I2:I2001,"PayPal") -> 695 | N2: =IF(J2>=1000,"High Value","Low Value") -> Low Value | O2: =TEXT(B2,"mmm-yyyy") -> Jul-2024 | P2: Cricket Bat | Q2: Sports | R2: Sarah Smith
A3: SALE1 | B3: 45285 | C3: CUST1467 | D3: PROD74 | E3: STORE17 | F3: 3 | G3: 104.47 | H3: 0.27 | I3: PayPal | J3: 228.7893 | K3: =SUM(J3:J2002) -> 2174196.3 | L3: =AVERAGE(J3:J2002) -> 1087.642 | M3: =COUNTIF(I3:I2002,"PayPal") -> 695 | N3: =IF(J3>=1000,"High Value","Low Value") -> Low Value | O3: =TEXT(B3,"mmm-yyyy") -> Dec-2023 | P3: Bluetooth Car Audio System | Q3: Electronics | R3: Michael Foley
A4: SALE2 | B4: 45446 | C4: CUST1056 | D4: PROD49 | E4: STORE8 | F4: 4 | G4: 914.05 | H4: 0.25 | I4: Credit Card | J4: 2742.15 | K4: =SUM(J4:J2003) -> 2173967.5 | L4: =AVERAGE(J4:J2003) -> 1088.0718 | M4: =COUNTIF(I4:I2003,"PayPal") -> 694 | N4: =IF(J4>=1000,"High Value","Low Value") -> High Value | O4: =TEXT(B4,"mmm-yyyy") -> Jun-2024 | P4: Men's Roll-On Perfume | Q4: Beauty | R4: Christopher Sutton
A5: SALE3 | B5: 45259 | C5: CUST1346 | D5: PROD76 | E5: STORE8 | F5: 1 | G5: 921.51 | H5: 0.16 | I5: COD | J5: 774.0684 | K5: =SUM(J5:J2004) -> 2171225.3 | L5: =AVERAGE(J5:J2004) -> 1087.2435 | M5: =COUNTIF(I5:I2004,"PayPal") -> 694 | N5: =IF(J5>=1000,"High Value","Low Value") -> Low Value | O5: =TEXT(B5,"mmm-yyyy") -> Nov-2023 | P5: Wireless Mouse | Q5: Electronics | R5: John Jordan | V5: Row Labels | W5: Sum of Total_Amount | AA5: Row Labels | AB5: Sum of Total_Amount
A6: SALE4 | B6: 45297 | C6: CUST1493 | D6: PROD59 | E6: STORE5 | F6: 3 | G6: 745.3 | H6: 0.18 | I6: Credit Card | J6: 1833.438 | K6: =SUM(J6:J2005) -> 2170451.3 | L6: =AVERAGE(J6:J2005) -> 1087.4004 | M6: =COUNTIF(I6:I2005,"PayPal") -> 694 | N6: =IF(J6>=1000,"High Value","Low Value") -> High Value | O6: =TEXT(B6,"mmm-yyyy") -> Jan-2024 | P6: Men's Hair Styling Gel | Q6: Beauty | R6: Amanda Powell | V6: Beauty | W6: 321561.33 | AA6: COD | AB6: 702459.42
A7: SALE5 | B7: 45499 | C7: CUST1116 | D7: PROD15 | E7: STORE7 | F7: 3 | G7: 147.01 | H7: 0.19 | I7: COD | J7: 357.2343 | K7: =SUM(J7:J2006) -> 2168617.8 | L7: =AVERAGE(J7:J2006) -> 1087.0265 | M7: =COUNTIF(I7:I2006,"PayPal") -> 694 | N7: =IF(J7>=1000,"High Value","Low Value") -> Low Value | O7: =TEXT(B7,"mmm-yyyy") -> Jul-2024 | P7: 4K Home Projector | Q7: Electronics | R7: Anthony Phillips | V7: Clothing | W7: 379216.04 | AA7: Credit Card | AB7: 715180.71
A8: SALE6 | B8: 45850 | C8: CUST1016 | D8: PROD56 | E8: STORE4 | F8: 2 | G8: 785.31 | H8: 0.15 | I8: PayPal | J8: 1335.027 | K8: =SUM(J8:J2007) -> 2168260.6 | L8: =AVERAGE(J8:J2007) -> 1087.3925 | M8: =COUNTIF(I8:I2007,"PayPal") -> 694 | N8: =IF(J8>=1000,"High Value","Low Value") -> High Value | O8: =TEXT(B8,"mmm-yyyy") -> Jul-2025 | P8: Premium Blanket Throw | Q8: Home | R8: John Scott | V8: Electronics | W8: 504311.35 | AA8: PayPal | AB8: 756754.57
A9: SALE7 | B9: 45248 | C9: CUST1152 | D9: PROD70 | E9: STORE8 | F9: 4 | G9: 342.39 | H9: 0.23 | I9: PayPal | J9: 1054.5612 | K9: =SUM(J9:J2008) -> 2166925.6 | L9: =AVERAGE(J9:J2008) -> 1087.2682 | M9: =COUNTIF(I9:I2008,"PayPal") -> 693 | N9: =IF(J9>=1000,"High Value","Low Value") -> High Value | O9: =TEXT(B9,"mmm-yyyy") -> Nov-2023 | P9: Kitchen Storage Rack | Q9: Home | R9: Patrick Roberts | V9: Home | W9: 427295.8 | AA9: Grand Total | AB9: 2174394.7
A10: SALE8 | B10: 45781 | C10: CUST1187 | D10: PROD99 | E10: STORE5 | F10: 3 | G10: 448.25 | H10: 0.07 | I10: PayPal | J10: 1250.6175 | K10: =SUM(J10:J2009) -> 2165871 | L10: =AVERAGE(J10:J2009) -> 1087.2846 | M10: =COUNTIF(I10:I2009,"PayPal") -> 692 | N10: =IF(J10>=1000,"High Value","Low Value") -> High Value | O10: =TEXT(B10,"mmm-yyyy") -> May-2025 | P10: Stainless Steel Cookware Set | Q10: Home | R10: Dr. Suzanne Bullock | V10: Sports | W10: 542010.17
A11: SALE9 | B11: 45869 | C11: CUST1464 | D11: PROD33 | E11: STORE0 | F11: 2 | G11: 873.17 | H11: 0.23 | I11: PayPal | J11: 1344.6818 | K11: =SUM(J11:J2010) -> 2164620.4 | L11: =AVERAGE(J11:J2010) -> 1087.2026 | M11: =COUNTIF(I11:I2010,"PayPal") -> 691 | N11: =IF(J11>=1000,"High Value","Low Value") -> High Value | O11: =TEXT(B11,"mmm-yyyy") -> Jul-2025 | P11: Modern Wall Clock | Q11: Home | R11: David Pierce | V11: Grand Total | W11: 2174394.7
A12: SALE10 | B12: 45335 | C12: CUST1065 | D12: PROD24 | E12: STORE14 | F12: 1 | G12: 278.63 | H12: 0.07 | I12: Credit Card | J12: 259.1259 | K12: =SUM(J12:J2011) -> 2163275.7 | L12: =AVERAGE(J12:J2011) -> 1087.0732 | M12: =COUNTIF(I12:I2011,"PayPal") -> 690 | N12: =IF(J12>=1000,"High Value","Low Value") -> Low Value | O12: =TEXT(B12,"mmm-yyyy") -> Feb-2024 | P12: Foldable Camping Chair | Q12: Sports | R12: Michael Thomas
A13: SALE11 | B13: 45801 | C13: CUST1320 | D13: PROD39 | E13: STORE1 | F13: 4 | G13: 286.92 | H13: 0.17 | I13: Credit Card | J13: 952.5744 | K13: =SUM(J13:J2012) -> 2163016.6 | L13: =AVERAGE(J13:J2012) -> 1087.4895 | M13: =COUNTIF(I13:I2012,"PayPal") -> 690 | N13: =IF(J13>=1000,"High Value","Low Value") -> Low Value | O13: =TEXT(B13,"mmm-yyyy") -> May-2025 | P13: Portable Power Bank | Q13: Electronics | R13: Jessica Gonzalez
A14: SALE12 | B14: 45528 | C14: CUST1237 | D14: PROD88 | E14: STORE4 | F14: 4 | G14: 644.58 | H14: 0.01 | I14: Credit Card | J14: 2552.5368 | K14: =SUM(J14:J2013) -> 2162064 | L14: =AVERAGE(J14:J2013) -> 1087.5574 | M14: =COUNTIF(I14:I2013,"PayPal") -> 690 | N14: =IF(J14>=1000,"High Value","Low Value") -> High Value | O14: =TEXT(B14,"mmm-yyyy") -> Aug-2024 | P14: Sports Wrist Sweatbands | Q14: Sports | R14: Wesley Short
A15: SALE13 | B15: 45875 | C15: CUST1443 | D15: PROD34 | E15: STORE16 | F15: 2 | G15: 316.9 | H15: 0.3 | I15: PayPal | J15: 443.66 | K15: =SUM(J15:J2014) -> 2159511.5 | L15: =AVERAGE(J15:J2014) -> 1086.8201 | M15: =COUNTIF(I15:I2014,"PayPal") -> 690 | N15: =IF(J15>=1000,"High Value","Low Value") -> Low Value | O15: =TEXT(B15,"mmm-yyyy") -> Aug-2025 | P15: Gaming Mechanical Keyboard | Q15: Electronics | R15: Adam Castro
A16: SALE14 | B16: 45829 | C16: CUST1348 | D16: PROD24 | E16: STORE15 | F16: 4 | G16: 403.47 | H16: 0.29 | I16: PayPal | J16: 1145.8548 | K16: =SUM(J16:J2015) -> 2159067.8 | L16: =AVERAGE(J16:J2015) -> 1087.1439 | M16: =COUNTIF(I16:I2015,"PayPal") -> 689 | N16: =IF(J16>=1000,"High Value","Low Value") -> High Value | O16: =TEXT(B16,"mmm-yyyy") -> Jun-2025 | P16: Foldable Camping Chair | Q16: Sports | R16: Sherry Cabrera | V16: Row Labels | W16: Sum of Quantity
A17: SALE15 | B17: 45636 | C17: CUST1435 | D17: PROD36 | E17: STORE9 | F17: 3 | G17: 871.34 | H17: 0.04 | I17: COD | J17: 2509.4592 | K17: =SUM(J17:J2016) -> 2157922 | L17: =AVERAGE(J17:J2016) -> 1087.1143 | M17: =COUNTIF(I17:I2016,"PayPal") -> 688 | N17: =IF(J17>=1000,"High Value","Low Value") -> High Value | O17: =TEXT(B17,"mmm-yyyy") -> Dec-2024 | P17: Women's Summer Dress | Q17: Clothing | R17: Lindsay Beasley | V17: Aaron Luna | W17: 7
A18: SALE16 | B18: 45913 | C18: CUST1276 | D18: PROD65 | E18: STORE19 | F18: 2 | G18: 451.98 | H18: 0.25 | I18: Credit Card | J18: 677.97 | K18: =SUM(J18:J2017) -> 2155412.5 | L18: =AVERAGE(J18:J2017) -> 1086.3974 | M18: =COUNTIF(I18:I2017,"PayPal") -> 688 | N18: =IF(J18>=1000,"High Value","Low Value") -> Low Value | O18: =TEXT(B18,"mmm-yyyy") -> Sep-2025 | P18: Adjustable Dumbbells 20kg | Q18: Sports | R18: Arthur Warren | V18: COD | W18: 3
A19: SALE17 | B19: 45637 | C19: CUST1079 | D19: PROD27 | E19: STORE4 | F19: 2 | G19: 502.69 | H19: 0.23 | I19: Credit Card | J19: 774.1426 | K19: =SUM(J19:J2018) -> 2154734.5 | L19: =AVERAGE(J19:J2018) -> 1086.6034 | M19: =COUNTIF(I19:I2018,"PayPal") -> 688 | N19: =IF(J19>=1000,"High Value","Low Value") -> Low Value | O19: =TEXT(B19,"mmm-yyyy") -> Dec-2024 | P19: Decorative Floor Vase | Q19: Home | R19: Molly Gardner | V19: Credit Card | W19: 1
A20: SALE18 | B20: 45517 | C20: CUST1094 | D20: PROD39 | E20: STORE4 | F20: 2 | G20: 559.23 | H20: 0.25 | I20: COD | J20: 838.845 | K20: =SUM(J20:J2019) -> 2153960.4 | L20: =AVERAGE(J20:J2019) -> 1086.761 | M20: =COUNTIF(I20:I2019,"PayPal") -> 688 | N20: =IF(J20>=1000,"High Value","Low Value") -> Low Value | O20: =TEXT(B20,"mmm-yyyy") -> Aug-2024 | P20: Portable Power Bank | Q20: Electronics | R20: David Patterson | V20: PayPal | W20: 3
A21: SALE19 | B21: 45369 | C21: CUST1239 | D21: PROD60 | E21: STORE13 | F21: 4 | G21: 464.18 | H21: 0.04 | I21: COD | J21: 1782.4512 | K21: =SUM(J21:J2020) -> 2153121.5 | L21: =AVERAGE(J21:J2020) -> 1086.8862 | M21: =COUNTIF(I21:I2020,"PayPal") -> 688 | N21: =IF(J21>=1000,"High Value","Low Value") -> High Value | O21: =TEXT(B21,"mmm-yyyy") -> Mar-2024 | P21: Luxury Perfume Spray | Q21: Beauty | R21: Maria Hill | V21: Adam Castro | W21: 16
A22: SALE20 | B22: 45843 | C22: CUST1144 | D22: PROD72 | E22: STORE17 | F22: 3 | G22: 986.04 | H22: 0.27 | I22: COD | J22: 2159.4276 | K22: =SUM(J22:J2021) -> 2151339.1 | L22: =AVERAGE(J22:J2021) -> 1086.5349 | M22: =COUNTIF(I22:I2021,"PayPal") -> 688 | N22: =IF(J22>=1000,"High Value","Low Value") -> High Value | O22: =TEXT(B22,"mmm-yyyy") -> Jul-2025 | P22: Professional Jump Rope | Q22: Sports | R22: Justin Cross | V22: COD | W22: 4
A23: SALE21 | B23: 45447 | C23: CUST1396 | D23: PROD43 | E23: STORE18 | F23: 1 | G23: 589.56 | H23: 0.22 | I23: Credit Card | J23: 459.8568 | K23: =SUM(J23:J2022) -> 2149179.7 | L23: =AVERAGE(J23:J2022) -> 1085.9928 | M23: =COUNTIF(I23:I2022,"PayPal") -> 688 | N23: =IF(J23>=1000,"High Value","Low Value") -> Low Value | O23: =TEXT(B23,"mmm-yyyy") -> Jun-2024 | P23: USB External Hard Drive | Q23: Electronics | R23: Alexander Byrd | V23: Credit Card | W23: 5
A24: SALE22 | B24: 45394 | C24: CUST1476 | D24: PROD69 | E24: STORE10 | F24: 3 | G24: 979.42 | H24: 0.03 | I24: PayPal | J24: 2850.1122 | K24: =SUM(J24:J2023) -> 2148719.8 | L24: =AVERAGE(J24:J2023) -> 1086.3093 | M24: =COUNTIF(I24:I2023,"PayPal") -> 688 | N24: =IF(J24>=1000,"High Value","Low Value") -> High Value | O24: =TEXT(B24,"mmm-yyyy") -> Apr-2024 | P24: Men's Sports Shorts | Q24: Clothing | R24: Elizabeth Foster | V24: PayPal | W24: 7
A25: SALE23 | B25: 45466 | C25: CUST1368 | D25: PROD12 | E25: STORE8 | F25: 1 | G25: 719.28 | H25: 0.08 | I25: Credit Card | J25: 661.7376 | K25: =SUM(J25:J2024) -> 2145869.7 | L25: =AVERAGE(J25:J2024) -> 1085.4171 | M25: =COUNTIF(I25:I2024,"PayPal") -> 687 | N25: =IF(J25>=1000,"High Value","Low Value") -> Low Value | O25: =TEXT(B25,"mmm-yyyy") -> Jun-2024 | P25: Hair Strengthening Shampoo | Q25: Beauty | R25: Miranda King | V25: Adam Cruz | W25: 14
A26: SALE24 | B26: 45908 | C26: CUST1186 | D26: PROD67 | E26: STORE6 | F26: 3 | G26: 77.6 | H26: 0.07 | I26: Credit Card | J26: 216.504 | K26: =SUM(J26:J2025) -> 2145208 | L26: =AVERAGE(J26:J2025) -> 1085.6316 | M26: =COUNTIF(I26:I2025,"PayPal") -> 687 | N26: =IF(J26>=1000,"High Value","Low Value") -> Low Value | O26: =TEXT(B26,"mmm-yyyy") -> Sep-2025 | P26: Smart LED Light Strip | Q26: Electronics | R26: Jennifer Pruitt | V26: COD | W26: 4
A27: SALE25 | B27: 45552 | C27: CUST1381 | D27: PROD5 | E27: STORE3 | F27: 4 | G27: 852.71 | H27: 0.14 | I27: PayPal | J27: 2933.3224 | K27: =SUM(J27:J2026) -> 2144991.5 | L27: =AVERAGE(J27:J2026) -> 1086.0716 | M27: =COUNTIF(I27:I2026,"PayPal") -> 687 | N27: =IF(J27>=1000,"High Value","Low Value") -> High Value | O27: =TEXT(B27,"mmm-yyyy") -> Sep-2024 | P27: Men's Leather Belt | Q27: Clothing | R27: Erika Padilla | V27: Credit Card | W27: 1
A28: SALE26 | B28: 45294 | C28: CUST1213 | D28: PROD98 | E28: STORE8 | F28: 4 | G28: 156.16 | H28: 0.04 | I28: Credit Card | J28: 599.6544 | K28: =SUM(J28:J2027) -> 2142058.1 | L28: =AVERAGE(J28:J2027) -> 1085.1358 | M28: =COUNTIF(I28:I2027,"PayPal") -> 686 | N28: =IF(J28>=1000,"High Value","Low Value") -> Low Value | O28: =TEXT(B28,"mmm-yyyy") -> Jan-2024 | P28: Portable Bluetooth Speaker | Q28: Electronics | R28: Stuart Johnson | V28: PayPal | W28: 9
... A1604: SALE1602 | B1604: 45313 | C1604: CUST1181 | D1604: PROD67 | E1604: STORE0 | F1604: 1 | G1604: 305.71 | H1604: 0.26 | I1604: COD | J1604: 226.2254 | K1604: =SUM(J1604:J3603) -> 425602.05 | L1604: =AVERAGE(J1604:J3603) -> 1069.3519 | M1604: =COUNTIF(I1604:I3603,"PayPal") -> 121 | N1604: =IF(J1604>=1000,"High Value","Low Value") -> Low Value | O1604: =TEXT(B1604,"mmm-yyyy") -> Jan-2024 | P1604: Smart LED Light Strip | Q1604: Electronics | R1604: Erin Ward | V1604: PayPal | W1604: 5
A1605: SALE1603 | B1605: 45224 | C1605: CUST1121 | D1605: PROD10 | E1605: STORE18 | F1605: 2 | G1605: 635.39 | H1605: 0.29 | I1605: COD | J1605: 902.2538 | K1605: =SUM(J1605:J3604) -> 425375.82 | L1605: =AVERAGE(J1605:J3604) -> 1071.4756 | M1605: =COUNTIF(I1605:I3604,"PayPal") -> 121 | N1605: =IF(J1605>=1000,"High Value","Low Value") -> Low Value | O1605: =TEXT(B1605,"mmm-yyyy") -> Oct-2023 | P1605: Ceramic Kitchen Bowl Set | Q1605: Home | R1605: Joel Robinson | V1605: (blank)
A1606: SALE1604 | B1606: 45491 | C1606: CUST1116 | D1606: PROD92 | E1606: STORE19 | F1606: 2 | G1606: 253.87 | H1606: 0.23 | I1606: COD | J1606: 390.9598 | K1606: =SUM(J1606:J3605) -> 424473.57 | L1606: =AVERAGE(J1606:J3605) -> 1071.903 | M1606: =COUNTIF(I1606:I3605,"PayPal") -> 121 | N1606: =IF(J1606>=1000,"High Value","Low Value") -> Low Value | O1606: =TEXT(B1606,"mmm-yyyy") -> Jul-2024 | P1606: Microwave Oven | Q1606: Home | R1606: Anthony Phillips | V1606: (blank)
A1607: SALE1605 | B1607: 45472 | C1607: CUST1484 | D1607: PROD76 | E1607: STORE17 | F1607: 3 | G1607: 915.81 | H1607: 0.17 | I1607: COD | J1607: 2280.3669 | K1607: =SUM(J1607:J3606) -> 424082.61 | L1607: =AVERAGE(J1607:J3606) -> 1073.6269 | M1607: =COUNTIF(I1607:I3606,"PayPal") -> 121 | N1607: =IF(J1607>=1000,"High Value","Low Value") -> High Value | O1607: =TEXT(B1607,"mmm-yyyy") -> Jun-2024 | P1607: Wireless Mouse | Q1607: Electronics | R1607: Jessica Castro | V1607: Grand Total | W1607: 4964
A1608: SALE1606 | B1608: 45795 | C1608: CUST1209 | D1608: PROD42 | E1608: STORE8 | F1608: 3 | G1608: 779.5 | H1608: 0.02 | I1608: Credit Card | J1608: 2291.73 | K1608: =SUM(J1608:J3607) -> 421802.24 | L1608: =AVERAGE(J1608:J3607) -> 1070.5641 | M1608: =COUNTIF(I1608:I3607,"PayPal") -> 121 | N1608: =IF(J1608>=1000,"High Value","Low Value") -> High Value | O1608: =TEXT(B1608,"mmm-yyyy") -> May-2025 | P1608: Smart Home WiFi Camera | Q1608: Electronics | R1608: Joan Johnson
A1609: SALE1607 | B1609: 45470 | C1609: CUST1469 | D1609: PROD61 | E1609: STORE16 | F1609: 2 | G1609: 780.57 | H1609: 0.26 | I1609: Credit Card | J1609: 1155.2436 | K1609: =SUM(J1609:J3608) -> 419510.51 | L1609: =AVERAGE(J1609:J3608) -> 1067.4568 | M1609: =COUNTIF(I1609:I3608,"PayPal") -> 121 | N1609: =IF(J1609>=1000,"High Value","Low Value") -> High Value | O1609: =TEXT(B1609,"mmm-yyyy") -> Jun-2024 | P1609: Tennis Ball 3-Pack | Q1609: Sports | R1609: James Foster
A1610: SALE1608 | B1610: 45390 | C1610: CUST1383 | D1610: PROD95 | E1610: STORE19 | F1610: 1 | G1610: 511.35 | H1610: 0 | I1610: Credit Card | J1610: 511.35 | K1610: =SUM(J1610:J3609) -> 418355.27 | L1610: =AVERAGE(J1610:J3609) -> 1067.2328 | M1610: =COUNTIF(I1610:I3609,"PayPal") -> 121 | N1610: =IF(J1610>=1000,"High Value","Low Value") -> Low Value | O1610: =TEXT(B1610,"mmm-yyyy") -> Apr-2024 | P1610: Sports Stopwatch Basic | Q1610: Sports | R1610: Kristine Higgins
A1611: SALE1609 | B1611: 45803 | C1611: CUST1016 | D1611: PROD97 | E1611: STORE3 | F1611: 4 | G1611: 44.07 | H1611: 0.29 | I1611: COD | J1611: 125.1588 | K1611: =SUM(J1611:J3610) -> 417843.92 | L1611: =AVERAGE(J1611:J3610) -> 1068.6545 | M1611: =COUNTIF(I1611:I3610,"PayPal") -> 121 | N1611: =IF(J1611>=1000,"High Value","Low Value") -> Low Value | O1611: =TEXT(B1611,"mmm-yyyy") -> May-2025 | P1611: Cricket Bat | Q1611: Sports | R1611: John Scott
A1612: SALE1610 | B1612: 45320 | C1612: CUST1197 | D1612: PROD69 | E1612: STORE11 | F1612: 2 | G1612: 895.92 | H1612: 0.15 | I1612: Credit Card | J1612: 1523.064 | K1612: =SUM(J1612:J3611) -> 417718.76 | L1612: =AVERAGE(J1612:J3611) -> 1071.0737 | M1612: =COUNTIF(I1612:I3611,"PayPal") -> 121 | N1612: =IF(J1612>=1000,"High Value","Low Value") -> High Value | O1612: =TEXT(B1612,"mmm-yyyy") -> Jan-2024 | P1612: Men's Sports Shorts | Q1612: Clothing | R1612: Andrea Jacobs
A1613: SALE1611 | B1613: 45619 | C1613: CUST1305 | D1613: PROD53 | E1613: STORE2 | F1613: 4 | G1613: 456.32 | H1613: 0.22 | I1613: COD | J1613: 1423.7184 | K1613: =SUM(J1613:J3612) -> 416195.7 | L1613: =AVERAGE(J1613:J3612) -> 1069.9118 | M1613: =COUNTIF(I1613:I3612,"PayPal") -> 121 | N1613: =IF(J1613>=1000,"High Value","Low Value") -> High Value | O1613: =TEXT(B1613,"mmm-yyyy") -> Nov-2024 | P1613: Men's Track Pants | Q1613: Clothing | R1613: Roberta Green
A1614: SALE1612 | B1614: 45777 | C1614: CUST1420 | D1614: PROD34 | E1614: STORE0 | F1614: 1 | G1614: 905.5 | H1614: 0.29 | I1614: COD | J1614: 642.905 | K1614: =SUM(J1614:J3613) -> 414771.98 | L1614: =AVERAGE(J1614:J3613) -> 1068.9999 | M1614: =COUNTIF(I1614:I3613,"PayPal") -> 121 | N1614: =IF(J1614>=1000,"High Value","Low Value") -> Low Value | O1614: =TEXT(B1614,"mmm-yyyy") -> Apr-2025 | P1614: Gaming Mechanical Keyboard | Q1614: Electronics | R1614: Dr. Tamara White Md
A1615: SALE1613 | B1615: 45523 | C1615: CUST1204 | D1615: PROD16 | E1615: STORE13 | F1615: 3 | G1615: 63.19 | H1615: 0.08 | I1615: Credit Card | J1615: 174.4044 | K1615: =SUM(J1615:J3614) -> 414129.07 | L1615: =AVERAGE(J1615:J3614) -> 1070.101 | M1615: =COUNTIF(I1615:I3614,"PayPal") -> 121 | N1615: =IF(J1615>=1000,"High Value","Low Value") -> Low Value | O1615: =TEXT(B1615,"mmm-yyyy") -> Aug-2024 | P1615: Beard Grooming Kit | Q1615: Beauty | R1615: Tiffany Herrera
...

Sheet Descriptive StatisticsStatistic
A1: Statistic | B1: Total Amount | C1: Formula
A2: Mean | B2: =AVERAGE(Sales_Fact!J2:J2001) -> 1087.1973 | C2: =AVERAGE(Sales_Fact!J2:J2001)
A3: Median | B3: =MEDIAN(Sales_Fact!J2:J2001) -> 868.7182 | C3: =MEDIAN(Sales_Fact!J2:J2001)
A4: Mode | B4: =IFERROR(_xlfn.MODE.SNGL(Sales_Fact!J2),"No repeated value") -> No repeated value | C4: =IFERROR(MODE.SNGL(Sales_Fact!J2),"No repeated value")
A5: Standard Deviation | B5: =_xlfn.STDEV.S(Sales_Fact!J2:J2001) -> 819.61896 | C5: =STDEV.S(Sales_Fact!J2:J2001)
A6: Minimum | B6: =MIN(Sales_Fact!J2:J2001) -> 18.459 | C6: =MIN(Sales_Fact!J2:J2001)
A7: Maximum | B7: =MAX(Sales_Fact!J2:J2001) -> 3908.2428 | C7: =MAX(Sales_Fact!J2:J2001)
A8: Count | B8: =COUNT(Sales_Fact!J2:J2001) -> 2000 | C8: =COUNT(Sales_Fact!J2:J2001)
